*** Starting uWSGI 2.0.11.2 (64bit) on [Sun Oct 25 16:24:11 2015] ***
compiled with version: 4.4.7 20120313 (Red Hat 4.4.7-4) on 24 October 2015 19:34:43
os: Linux-2.6.32-431.el6.x86_64 #1 SMP Fri Nov 22 03:15:09 UTC 2013
nodename: localhost.localdomain
machine: x86_64
clock source: unix
pcre jit disabled
detected number of CPU cores: 1
current working directory: /home/fious/mysite
detected binary path: /home/fious/uwsgi/uwsgi
chdir() to /home/fious/mysite/mysite
your processes number limit is 1024
your memory page size is 4096 bytes
detected max file descriptor number: 1024
lock engine: pthread robust mutexes
thunder lock: disabled (you can enable it with --thunder-lock)
uwsgi socket 0 bound to TCP address :8001 fd 3
Python version: 3.4.2 (default, Oct 18 2015, 15:32:19)  [GCC 4.4.7 20120313 (Red Hat 4.4.7-4)]
Python main interpreter initialized at 0xecaf00
python threads support enabled
your server socket listen backlog is limited to 100 connections
your mercy for graceful operations on workers is 60 seconds
mapped 145520 bytes (142 KB) for 1 cores
*** Operational MODE: single process ***
added /home/fious/mysite/ to pythonpath.
WSGI app 0 (mountpoint='') ready in 0 seconds on interpreter 0xecaf00 pid: 3419 (default app)
*** uWSGI is running in multiple interpreter mode ***
spawned uWSGI master process (pid: 3419)
spawned uWSGI worker 1 (pid: 3421, cores: 1)
Internal Server Error: /hello/
Traceback (most recent call last):
  File "/home/fious/python3.4.2/lib/python3.4/site-packages/Django-1.8.4-py3.4.egg/django/core/urlresolvers.py", line 394, in urlconf_module
    return self._urlconf_module
AttributeError: 'RegexURLResolver' object has no attribute '_urlconf_module'

During handling of the above exception, another exception occurred:

Traceback (most recent call last):
  File "/home/fious/python3.4.2/lib/python3.4/site-packages/Django-1.8.4-py3.4.egg/django/core/handlers/base.py", line 119, in get_response
    resolver_match = resolver.resolve(request.path_info)
  File "/home/fious/python3.4.2/lib/python3.4/site-packages/Django-1.8.4-py3.4.egg/django/core/urlresolvers.py", line 366, in resolve
    for pattern in self.url_patterns:
  File "/home/fious/python3.4.2/lib/python3.4/site-packages/Django-1.8.4-py3.4.egg/django/core/urlresolvers.py", line 402, in url_patterns
    patterns = getattr(self.urlconf_module, "urlpatterns", self.urlconf_module)
  File "/home/fious/python3.4.2/lib/python3.4/site-packages/Django-1.8.4-py3.4.egg/django/core/urlresolvers.py", line 396, in urlconf_module
    self._urlconf_module = import_module(self.urlconf_name)
  File "/home/fious/python3.4.2/lib/python3.4/importlib/__init__.py", line 109, in import_module
    return _bootstrap._gcd_import(name[level:], package, level)
  File "<frozen importlib._bootstrap>", line 2254, in _gcd_import
  File "<frozen importlib._bootstrap>", line 2237, in _find_and_load
  File "<frozen importlib._bootstrap>", line 2226, in _find_and_load_unlocked
  File "<frozen importlib._bootstrap>", line 1200, in _load_unlocked
  File "<frozen importlib._bootstrap>", line 1129, in _exec
  File "<frozen importlib._bootstrap>", line 1471, in exec_module
  File "<frozen importlib._bootstrap>", line 321, in _call_with_frames_removed
  File "/home/fious/mysite/mysite/urls.py", line 12, in <module>
    admin.autodiscover()
  File "/home/fious/python3.4.2/lib/python3.4/site-packages/Django-1.8.4-py3.4.egg/django/contrib/admin/__init__.py", line 24, in autodiscover
    autodiscover_modules('admin', register_to=site)
  File "/home/fious/python3.4.2/lib/python3.4/site-packages/Django-1.8.4-py3.4.egg/django/utils/module_loading.py", line 67, in autodiscover_modules
    for app_config in apps.get_app_configs():
  File "/home/fious/python3.4.2/lib/python3.4/site-packages/Django-1.8.4-py3.4.egg/django/apps/registry.py", line 137, in get_app_configs
    self.check_apps_ready()
  File "/home/fious/python3.4.2/lib/python3.4/site-packages/Django-1.8.4-py3.4.egg/django/apps/registry.py", line 124, in check_apps_ready
    raise AppRegistryNotReady("Apps aren't loaded yet.")
django.core.exceptions.AppRegistryNotReady: Apps aren't loaded yet.
Traceback (most recent call last):
  File "/home/fious/python3.4.2/lib/python3.4/site-packages/Django-1.8.4-py3.4.egg/django/core/urlresolvers.py", line 394, in urlconf_module
    return self._urlconf_module
AttributeError: 'RegexURLResolver' object has no attribute '_urlconf_module'

During handling of the above exception, another exception occurred:

Traceback (most recent call last):
  File "/home/fious/python3.4.2/lib/python3.4/site-packages/Django-1.8.4-py3.4.egg/django/core/handlers/base.py", line 119, in get_response
    resolver_match = resolver.resolve(request.path_info)
  File "/home/fious/python3.4.2/lib/python3.4/site-packages/Django-1.8.4-py3.4.egg/django/core/urlresolvers.py", line 366, in resolve
    for pattern in self.url_patterns:
  File "/home/fious/python3.4.2/lib/python3.4/site-packages/Django-1.8.4-py3.4.egg/django/core/urlresolvers.py", line 402, in url_patterns
    patterns = getattr(self.urlconf_module, "urlpatterns", self.urlconf_module)
  File "/home/fious/python3.4.2/lib/python3.4/site-packages/Django-1.8.4-py3.4.egg/django/core/urlresolvers.py", line 396, in urlconf_module
    self._urlconf_module = import_module(self.urlconf_name)
  File "/home/fious/python3.4.2/lib/python3.4/importlib/__init__.py", line 109, in import_module
    return _bootstrap._gcd_import(name[level:], package, level)
  File "<frozen importlib._bootstrap>", line 2254, in _gcd_import
  File "<frozen importlib._bootstrap>", line 2237, in _find_and_load
  File "<frozen importlib._bootstrap>", line 2226, in _find_and_load_unlocked
  File "<frozen importlib._bootstrap>", line 1200, in _load_unlocked
  File "<frozen importlib._bootstrap>", line 1129, in _exec
  File "<frozen importlib._bootstrap>", line 1471, in exec_module
  File "<frozen importlib._bootstrap>", line 321, in _call_with_frames_removed
  File "/home/fious/mysite/mysite/urls.py", line 12, in <module>
    admin.autodiscover()
  File "/home/fious/python3.4.2/lib/python3.4/site-packages/Django-1.8.4-py3.4.egg/django/contrib/admin/__init__.py", line 24, in autodiscover
    autodiscover_modules('admin', register_to=site)
  File "/home/fious/python3.4.2/lib/python3.4/site-packages/Django-1.8.4-py3.4.egg/django/utils/module_loading.py", line 67, in autodiscover_modules
    for app_config in apps.get_app_configs():
  File "/home/fious/python3.4.2/lib/python3.4/site-packages/Django-1.8.4-py3.4.egg/django/apps/registry.py", line 137, in get_app_configs
    self.check_apps_ready()
  File "/home/fious/python3.4.2/lib/python3.4/site-packages/Django-1.8.4-py3.4.egg/django/apps/registry.py", line 124, in check_apps_ready
    raise AppRegistryNotReady("Apps aren't loaded yet.")
django.core.exceptions.AppRegistryNotReady: Apps aren't loaded yet.

During handling of the above exception, another exception occurred:

Traceback (most recent call last):
  File "/home/fious/python3.4.2/lib/python3.4/site-packages/Django-1.8.4-py3.4.egg/django/template/defaultfilters.py", line 776, in date
    return formats.date_format(value, arg)
  File "/home/fious/python3.4.2/lib/python3.4/site-packages/Django-1.8.4-py3.4.egg/django/utils/formats.py", line 136, in date_format
    return dateformat.format(value, get_format(format or 'DATE_FORMAT', use_l10n=use_l10n))
  File "/home/fious/python3.4.2/lib/python3.4/site-packages/Django-1.8.4-py3.4.egg/django/utils/formats.py", line 123, in get_format
    return getattr(settings, format_type)
  File "/home/fious/python3.4.2/lib/python3.4/site-packages/Django-1.8.4-py3.4.egg/django/conf/__init__.py", line 49, in __getattr__
    return getattr(self._wrapped, name)
AttributeError: 'Settings' object has no attribute 'r'

During handling of the above exception, another exception occurred:

Traceback (most recent call last):
  File "/home/fious/python3.4.2/lib/python3.4/site-packages/Django-1.8.4-py3.4.egg/django/utils/translation/trans_real.py", line 161, in _add_installed_apps_translations
    app_configs = reversed(list(apps.get_app_configs()))
  File "/home/fious/python3.4.2/lib/python3.4/site-packages/Django-1.8.4-py3.4.egg/django/apps/registry.py", line 137, in get_app_configs
    self.check_apps_ready()
  File "/home/fious/python3.4.2/lib/python3.4/site-packages/Django-1.8.4-py3.4.egg/django/apps/registry.py", line 124, in check_apps_ready
    raise AppRegistryNotReady("Apps aren't loaded yet.")
django.core.exceptions.AppRegistryNotReady: Apps aren't loaded yet.

During handling of the above exception, another exception occurred:

Traceback (most recent call last):
  File "/home/fious/python3.4.2/lib/python3.4/site-packages/Django-1.8.4-py3.4.egg/django/core/handlers/wsgi.py", line 189, in __call__
    response = self.get_response(request)
  File "/home/fious/python3.4.2/lib/python3.4/site-packages/Django-1.8.4-py3.4.egg/django/core/handlers/base.py", line 218, in get_response
    response = self.handle_uncaught_exception(request, resolver, sys.exc_info())
  File "/home/fious/python3.4.2/lib/python3.4/site-packages/Django-1.8.4-py3.4.egg/django/core/handlers/base.py", line 261, in handle_uncaught_exception
    return debug.technical_500_response(request, *exc_info)
  File "/home/fious/python3.4.2/lib/python3.4/site-packages/Django-1.8.4-py3.4.egg/django/views/debug.py", line 97, in technical_500_response
    html = reporter.get_traceback_html()
  File "/home/fious/python3.4.2/lib/python3.4/site-packages/Django-1.8.4-py3.4.egg/django/views/debug.py", line 384, in get_traceback_html
    return t.render(c)
  File "/home/fious/python3.4.2/lib/python3.4/site-packages/Django-1.8.4-py3.4.egg/django/template/base.py", line 209, in render
    return self._render(context)
  File "/home/fious/python3.4.2/lib/python3.4/site-packages/Django-1.8.4-py3.4.egg/django/template/base.py", line 201, in _render
    return self.nodelist.render(context)
  File "/home/fious/python3.4.2/lib/python3.4/site-packages/Django-1.8.4-py3.4.egg/django/template/base.py", line 903, in render
    bit = self.render_node(node, context)
  File "/home/fious/python3.4.2/lib/python3.4/site-packages/Django-1.8.4-py3.4.egg/django/template/debug.py", line 79, in render_node
    return node.render(context)
  File "/home/fious/python3.4.2/lib/python3.4/site-packages/Django-1.8.4-py3.4.egg/django/template/debug.py", line 89, in render
    output = self.filter_expression.resolve(context)
  File "/home/fious/python3.4.2/lib/python3.4/site-packages/Django-1.8.4-py3.4.egg/django/template/base.py", line 674, in resolve
    new_obj = func(obj, *arg_vals)
  File "/home/fious/python3.4.2/lib/python3.4/site-packages/Django-1.8.4-py3.4.egg/django/template/defaultfilters.py", line 779, in date
    return format(value, arg)
  File "/home/fious/python3.4.2/lib/python3.4/site-packages/Django-1.8.4-py3.4.egg/django/utils/dateformat.py", line 345, in format
    return df.format(format_string)
  File "/home/fious/python3.4.2/lib/python3.4/site-packages/Django-1.8.4-py3.4.egg/django/utils/dateformat.py", line 37, in format
    pieces.append(force_text(getattr(self, piece)()))
  File "/home/fious/python3.4.2/lib/python3.4/site-packages/Django-1.8.4-py3.4.egg/django/utils/dateformat.py", line 270, in r
    return self.format('D, j M Y H:i:s O')
  File "/home/fious/python3.4.2/lib/python3.4/site-packages/Django-1.8.4-py3.4.egg/django/utils/dateformat.py", line 37, in format
    pieces.append(force_text(getattr(self, piece)()))
  File "/home/fious/python3.4.2/lib/python3.4/site-packages/Django-1.8.4-py3.4.egg/django/utils/encoding.py", line 90, in force_text
    s = six.text_type(s)
  File "/home/fious/python3.4.2/lib/python3.4/site-packages/Django-1.8.4-py3.4.egg/django/utils/functional.py", line 141, in __text_cast
    return func(*self.__args, **self.__kw)
  File "/home/fious/python3.4.2/lib/python3.4/site-packages/Django-1.8.4-py3.4.egg/django/utils/translation/__init__.py", line 84, in ugettext
    return _trans.ugettext(message)
  File "/home/fious/python3.4.2/lib/python3.4/site-packages/Django-1.8.4-py3.4.egg/django/utils/translation/trans_real.py", line 321, in gettext
    return do_translate(message, 'gettext')
  File "/home/fious/python3.4.2/lib/python3.4/site-packages/Django-1.8.4-py3.4.egg/django/utils/translation/trans_real.py", line 304, in do_translate
    _default = _default or translation(settings.LANGUAGE_CODE)
  File "/home/fious/python3.4.2/lib/python3.4/site-packages/Django-1.8.4-py3.4.egg/django/utils/translation/trans_real.py", line 206, in translation
    _translations[language] = DjangoTranslation(language)
  File "/home/fious/python3.4.2/lib/python3.4/site-packages/Django-1.8.4-py3.4.egg/django/utils/translation/trans_real.py", line 116, in __init__
    self._add_installed_apps_translations()
  File "/home/fious/python3.4.2/lib/python3.4/site-packages/Django-1.8.4-py3.4.egg/django/utils/translation/trans_real.py", line 164, in _add_installed_apps_translations
    "The translation infrastructure cannot be initialized before the "
django.core.exceptions.AppRegistryNotReady: The translation infrastructure cannot be initialized before the apps registry is ready. Check that you don't make non-lazy gettext calls at import time.
[pid: 3421|app: 0|req: 1/1] 127.0.0.1 () {38 vars in 607 bytes} [Sun Oct 25 08:25:17 2015] GET /hello/ => generated 0 bytes in 256 msecs (HTTP/1.1 500) 0 headers in 0 bytes (0 switches on core 0)
Internal Server Error: /hello/
Traceback (most recent call last):
  File "/home/fious/python3.4.2/lib/python3.4/site-packages/Django-1.8.4-py3.4.egg/django/core/urlresolvers.py", line 394, in urlconf_module
    return self._urlconf_module
AttributeError: 'RegexURLResolver' object has no attribute '_urlconf_module'

During handling of the above exception, another exception occurred:

Traceback (most recent call last):
  File "/home/fious/python3.4.2/lib/python3.4/site-packages/Django-1.8.4-py3.4.egg/django/core/handlers/base.py", line 119, in get_response
    resolver_match = resolver.resolve(request.path_info)
  File "/home/fious/python3.4.2/lib/python3.4/site-packages/Django-1.8.4-py3.4.egg/django/core/urlresolvers.py", line 366, in resolve
    for pattern in self.url_patterns:
  File "/home/fious/python3.4.2/lib/python3.4/site-packages/Django-1.8.4-py3.4.egg/django/core/urlresolvers.py", line 402, in url_patterns
    patterns = getattr(self.urlconf_module, "urlpatterns", self.urlconf_module)
  File "/home/fious/python3.4.2/lib/python3.4/site-packages/Django-1.8.4-py3.4.egg/django/core/urlresolvers.py", line 396, in urlconf_module
    self._urlconf_module = import_module(self.urlconf_name)
  File "/home/fious/python3.4.2/lib/python3.4/importlib/__init__.py", line 109, in import_module
    return _bootstrap._gcd_import(name[level:], package, level)
  File "<frozen importlib._bootstrap>", line 2254, in _gcd_import
  File "<frozen importlib._bootstrap>", line 2237, in _find_and_load
  File "<frozen importlib._bootstrap>", line 2226, in _find_and_load_unlocked
  File "<frozen importlib._bootstrap>", line 1200, in _load_unlocked
  File "<frozen importlib._bootstrap>", line 1129, in _exec
  File "<frozen importlib._bootstrap>", line 1471, in exec_module
  File "<frozen importlib._bootstrap>", line 321, in _call_with_frames_removed
  File "/home/fious/mysite/mysite/urls.py", line 12, in <module>
    admin.autodiscover()
  File "/home/fious/python3.4.2/lib/python3.4/site-packages/Django-1.8.4-py3.4.egg/django/contrib/admin/__init__.py", line 24, in autodiscover
    autodiscover_modules('admin', register_to=site)
  File "/home/fious/python3.4.2/lib/python3.4/site-packages/Django-1.8.4-py3.4.egg/django/utils/module_loading.py", line 67, in autodiscover_modules
    for app_config in apps.get_app_configs():
  File "/home/fious/python3.4.2/lib/python3.4/site-packages/Django-1.8.4-py3.4.egg/django/apps/registry.py", line 137, in get_app_configs
    self.check_apps_ready()
  File "/home/fious/python3.4.2/lib/python3.4/site-packages/Django-1.8.4-py3.4.egg/django/apps/registry.py", line 124, in check_apps_ready
    raise AppRegistryNotReady("Apps aren't loaded yet.")
django.core.exceptions.AppRegistryNotReady: Apps aren't loaded yet.
Traceback (most recent call last):
  File "/home/fious/python3.4.2/lib/python3.4/site-packages/Django-1.8.4-py3.4.egg/django/core/urlresolvers.py", line 394, in urlconf_module
    return self._urlconf_module
AttributeError: 'RegexURLResolver' object has no attribute '_urlconf_module'

During handling of the above exception, another exception occurred:

Traceback (most recent call last):
  File "/home/fious/python3.4.2/lib/python3.4/site-packages/Django-1.8.4-py3.4.egg/django/core/handlers/base.py", line 119, in get_response
    resolver_match = resolver.resolve(request.path_info)
  File "/home/fious/python3.4.2/lib/python3.4/site-packages/Django-1.8.4-py3.4.egg/django/core/urlresolvers.py", line 366, in resolve
    for pattern in self.url_patterns:
  File "/home/fious/python3.4.2/lib/python3.4/site-packages/Django-1.8.4-py3.4.egg/django/core/urlresolvers.py", line 402, in url_patterns
    patterns = getattr(self.urlconf_module, "urlpatterns", self.urlconf_module)
  File "/home/fious/python3.4.2/lib/python3.4/site-packages/Django-1.8.4-py3.4.egg/django/core/urlresolvers.py", line 396, in urlconf_module
    self._urlconf_module = import_module(self.urlconf_name)
  File "/home/fious/python3.4.2/lib/python3.4/importlib/__init__.py", line 109, in import_module
    return _bootstrap._gcd_import(name[level:], package, level)
  File "<frozen importlib._bootstrap>", line 2254, in _gcd_import
  File "<frozen importlib._bootstrap>", line 2237, in _find_and_load
  File "<frozen importlib._bootstrap>", line 2226, in _find_and_load_unlocked
  File "<frozen importlib._bootstrap>", line 1200, in _load_unlocked
  File "<frozen importlib._bootstrap>", line 1129, in _exec
  File "<frozen importlib._bootstrap>", line 1471, in exec_module
  File "<frozen importlib._bootstrap>", line 321, in _call_with_frames_removed
  File "/home/fious/mysite/mysite/urls.py", line 12, in <module>
    admin.autodiscover()
  File "/home/fious/python3.4.2/lib/python3.4/site-packages/Django-1.8.4-py3.4.egg/django/contrib/admin/__init__.py", line 24, in autodiscover
    autodiscover_modules('admin', register_to=site)
  File "/home/fious/python3.4.2/lib/python3.4/site-packages/Django-1.8.4-py3.4.egg/django/utils/module_loading.py", line 67, in autodiscover_modules
    for app_config in apps.get_app_configs():
  File "/home/fious/python3.4.2/lib/python3.4/site-packages/Django-1.8.4-py3.4.egg/django/apps/registry.py", line 137, in get_app_configs
    self.check_apps_ready()
  File "/home/fious/python3.4.2/lib/python3.4/site-packages/Django-1.8.4-py3.4.egg/django/apps/registry.py", line 124, in check_apps_ready
    raise AppRegistryNotReady("Apps aren't loaded yet.")
django.core.exceptions.AppRegistryNotReady: Apps aren't loaded yet.

During handling of the above exception, another exception occurred:

Traceback (most recent call last):
  File "/home/fious/python3.4.2/lib/python3.4/site-packages/Django-1.8.4-py3.4.egg/django/template/defaultfilters.py", line 776, in date
    return formats.date_format(value, arg)
  File "/home/fious/python3.4.2/lib/python3.4/site-packages/Django-1.8.4-py3.4.egg/django/utils/formats.py", line 136, in date_format
    return dateformat.format(value, get_format(format or 'DATE_FORMAT', use_l10n=use_l10n))
  File "/home/fious/python3.4.2/lib/python3.4/site-packages/Django-1.8.4-py3.4.egg/django/utils/formats.py", line 108, in get_format
    return getattr(settings, format_type)
  File "/home/fious/python3.4.2/lib/python3.4/site-packages/Django-1.8.4-py3.4.egg/django/conf/__init__.py", line 49, in __getattr__
    return getattr(self._wrapped, name)
AttributeError: 'Settings' object has no attribute 'r'

During handling of the above exception, another exception occurred:

Traceback (most recent call last):
  File "/home/fious/python3.4.2/lib/python3.4/site-packages/Django-1.8.4-py3.4.egg/django/utils/translation/trans_real.py", line 161, in _add_installed_apps_translations
    app_configs = reversed(list(apps.get_app_configs()))
  File "/home/fious/python3.4.2/lib/python3.4/site-packages/Django-1.8.4-py3.4.egg/django/apps/registry.py", line 137, in get_app_configs
    self.check_apps_ready()
  File "/home/fious/python3.4.2/lib/python3.4/site-packages/Django-1.8.4-py3.4.egg/django/apps/registry.py", line 124, in check_apps_ready
    raise AppRegistryNotReady("Apps aren't loaded yet.")
django.core.exceptions.AppRegistryNotReady: Apps aren't loaded yet.

During handling of the above exception, another exception occurred:

Traceback (most recent call last):
  File "/home/fious/python3.4.2/lib/python3.4/site-packages/Django-1.8.4-py3.4.egg/django/core/handlers/wsgi.py", line 189, in __call__
    response = self.get_response(request)
  File "/home/fious/python3.4.2/lib/python3.4/site-packages/Django-1.8.4-py3.4.egg/django/core/handlers/base.py", line 218, in get_response
    response = self.handle_uncaught_exception(request, resolver, sys.exc_info())
  File "/home/fious/python3.4.2/lib/python3.4/site-packages/Django-1.8.4-py3.4.egg/django/core/handlers/base.py", line 261, in handle_uncaught_exception
    return debug.technical_500_response(request, *exc_info)
  File "/home/fious/python3.4.2/lib/python3.4/site-packages/Django-1.8.4-py3.4.egg/django/views/debug.py", line 97, in technical_500_response
    html = reporter.get_traceback_html()
  File "/home/fious/python3.4.2/lib/python3.4/site-packages/Django-1.8.4-py3.4.egg/django/views/debug.py", line 384, in get_traceback_html
    return t.render(c)
  File "/home/fious/python3.4.2/lib/python3.4/site-packages/Django-1.8.4-py3.4.egg/django/template/base.py", line 209, in render
    return self._render(context)
  File "/home/fious/python3.4.2/lib/python3.4/site-packages/Django-1.8.4-py3.4.egg/django/template/base.py", line 201, in _render
    return self.nodelist.render(context)
  File "/home/fious/python3.4.2/lib/python3.4/site-packages/Django-1.8.4-py3.4.egg/django/template/base.py", line 903, in render
    bit = self.render_node(node, context)
  File "/home/fious/python3.4.2/lib/python3.4/site-packages/Django-1.8.4-py3.4.egg/django/template/debug.py", line 79, in render_node
    return node.render(context)
  File "/home/fious/python3.4.2/lib/python3.4/site-packages/Django-1.8.4-py3.4.egg/django/template/debug.py", line 89, in render
    output = self.filter_expression.resolve(context)
  File "/home/fious/python3.4.2/lib/python3.4/site-packages/Django-1.8.4-py3.4.egg/django/template/base.py", line 674, in resolve
    new_obj = func(obj, *arg_vals)
  File "/home/fious/python3.4.2/lib/python3.4/site-packages/Django-1.8.4-py3.4.egg/django/template/defaultfilters.py", line 779, in date
    return format(value, arg)
  File "/home/fious/python3.4.2/lib/python3.4/site-packages/Django-1.8.4-py3.4.egg/django/utils/dateformat.py", line 345, in format
    return df.format(format_string)
  File "/home/fious/python3.4.2/lib/python3.4/site-packages/Django-1.8.4-py3.4.egg/django/utils/dateformat.py", line 37, in format
    pieces.append(force_text(getattr(self, piece)()))
  File "/home/fious/python3.4.2/lib/python3.4/site-packages/Django-1.8.4-py3.4.egg/django/utils/dateformat.py", line 270, in r
    return self.format('D, j M Y H:i:s O')
  File "/home/fious/python3.4.2/lib/python3.4/site-packages/Django-1.8.4-py3.4.egg/django/utils/dateformat.py", line 37, in format
    pieces.append(force_text(getattr(self, piece)()))
  File "/home/fious/python3.4.2/lib/python3.4/site-packages/Django-1.8.4-py3.4.egg/django/utils/encoding.py", line 90, in force_text
    s = six.text_type(s)
  File "/home/fious/python3.4.2/lib/python3.4/site-packages/Django-1.8.4-py3.4.egg/django/utils/functional.py", line 141, in __text_cast
    return func(*self.__args, **self.__kw)
  File "/home/fious/python3.4.2/lib/python3.4/site-packages/Django-1.8.4-py3.4.egg/django/utils/translation/__init__.py", line 84, in ugettext
    return _trans.ugettext(message)
  File "/home/fious/python3.4.2/lib/python3.4/site-packages/Django-1.8.4-py3.4.egg/django/utils/translation/trans_real.py", line 321, in gettext
    return do_translate(message, 'gettext')
  File "/home/fious/python3.4.2/lib/python3.4/site-packages/Django-1.8.4-py3.4.egg/django/utils/translation/trans_real.py", line 304, in do_translate
    _default = _default or translation(settings.LANGUAGE_CODE)
  File "/home/fious/python3.4.2/lib/python3.4/site-packages/Django-1.8.4-py3.4.egg/django/utils/translation/trans_real.py", line 206, in translation
    _translations[language] = DjangoTranslation(language)
  File "/home/fious/python3.4.2/lib/python3.4/site-packages/Django-1.8.4-py3.4.egg/django/utils/translation/trans_real.py", line 116, in __init__
    self._add_installed_apps_translations()
  File "/home/fious/python3.4.2/lib/python3.4/site-packages/Django-1.8.4-py3.4.egg/django/utils/translation/trans_real.py", line 164, in _add_installed_apps_translations
    "The translation infrastructure cannot be initialized before the "
django.core.exceptions.AppRegistryNotReady: The translation infrastructure cannot be initialized before the apps registry is ready. Check that you don't make non-lazy gettext calls at import time.
[pid: 3421|app: 0|req: 2/2] 127.0.0.1 () {38 vars in 607 bytes} [Sun Oct 25 08:27:37 2015] GET /hello/ => generated 0 bytes in 116 msecs (HTTP/1.1 500) 0 headers in 0 bytes (0 switches on core 0)
*** Starting uWSGI 2.0.11.2 (64bit) on [Sun Oct 25 16:34:54 2015] ***
compiled with version: 4.4.7 20120313 (Red Hat 4.4.7-4) on 24 October 2015 19:34:43
os: Linux-2.6.32-431.el6.x86_64 #1 SMP Fri Nov 22 03:15:09 UTC 2013
nodename: localhost.localdomain
machine: x86_64
clock source: unix
pcre jit disabled
detected number of CPU cores: 1
current working directory: /home/fious/mysite
detected binary path: /home/fious/uwsgi/uwsgi
chdir() to /home/fious/mysite/mysite
your processes number limit is 1024
your memory page size is 4096 bytes
detected max file descriptor number: 1024
lock engine: pthread robust mutexes
thunder lock: disabled (you can enable it with --thunder-lock)
probably another instance of uWSGI is running on the same address (:8001).
bind(): Address already in use [core/socket.c line 769]
Internal Server Error: /hello/
Traceback (most recent call last):
  File "/home/fious/python3.4.2/lib/python3.4/site-packages/Django-1.8.4-py3.4.egg/django/core/urlresolvers.py", line 394, in urlconf_module
    return self._urlconf_module
AttributeError: 'RegexURLResolver' object has no attribute '_urlconf_module'

During handling of the above exception, another exception occurred:

Traceback (most recent call last):
  File "/home/fious/python3.4.2/lib/python3.4/site-packages/Django-1.8.4-py3.4.egg/django/core/handlers/base.py", line 119, in get_response
    resolver_match = resolver.resolve(request.path_info)
  File "/home/fious/python3.4.2/lib/python3.4/site-packages/Django-1.8.4-py3.4.egg/django/core/urlresolvers.py", line 366, in resolve
    for pattern in self.url_patterns:
  File "/home/fious/python3.4.2/lib/python3.4/site-packages/Django-1.8.4-py3.4.egg/django/core/urlresolvers.py", line 402, in url_patterns
    patterns = getattr(self.urlconf_module, "urlpatterns", self.urlconf_module)
  File "/home/fious/python3.4.2/lib/python3.4/site-packages/Django-1.8.4-py3.4.egg/django/core/urlresolvers.py", line 396, in urlconf_module
    self._urlconf_module = import_module(self.urlconf_name)
  File "/home/fious/python3.4.2/lib/python3.4/importlib/__init__.py", line 109, in import_module
    return _bootstrap._gcd_import(name[level:], package, level)
  File "<frozen importlib._bootstrap>", line 2254, in _gcd_import
  File "<frozen importlib._bootstrap>", line 2237, in _find_and_load
  File "<frozen importlib._bootstrap>", line 2226, in _find_and_load_unlocked
  File "<frozen importlib._bootstrap>", line 1200, in _load_unlocked
  File "<frozen importlib._bootstrap>", line 1129, in _exec
  File "<frozen importlib._bootstrap>", line 1471, in exec_module
  File "<frozen importlib._bootstrap>", line 321, in _call_with_frames_removed
  File "/home/fious/mysite/mysite/urls.py", line 12, in <module>
    admin.autodiscover()
  File "/home/fious/python3.4.2/lib/python3.4/site-packages/Django-1.8.4-py3.4.egg/django/contrib/admin/__init__.py", line 24, in autodiscover
    autodiscover_modules('admin', register_to=site)
  File "/home/fious/python3.4.2/lib/python3.4/site-packages/Django-1.8.4-py3.4.egg/django/utils/module_loading.py", line 67, in autodiscover_modules
    for app_config in apps.get_app_configs():
  File "/home/fious/python3.4.2/lib/python3.4/site-packages/Django-1.8.4-py3.4.egg/django/apps/registry.py", line 137, in get_app_configs
    self.check_apps_ready()
  File "/home/fious/python3.4.2/lib/python3.4/site-packages/Django-1.8.4-py3.4.egg/django/apps/registry.py", line 124, in check_apps_ready
    raise AppRegistryNotReady("Apps aren't loaded yet.")
django.core.exceptions.AppRegistryNotReady: Apps aren't loaded yet.
Traceback (most recent call last):
  File "/home/fious/python3.4.2/lib/python3.4/site-packages/Django-1.8.4-py3.4.egg/django/core/urlresolvers.py", line 394, in urlconf_module
    return self._urlconf_module
AttributeError: 'RegexURLResolver' object has no attribute '_urlconf_module'

During handling of the above exception, another exception occurred:

Traceback (most recent call last):
  File "/home/fious/python3.4.2/lib/python3.4/site-packages/Django-1.8.4-py3.4.egg/django/core/handlers/base.py", line 119, in get_response
    resolver_match = resolver.resolve(request.path_info)
  File "/home/fious/python3.4.2/lib/python3.4/site-packages/Django-1.8.4-py3.4.egg/django/core/urlresolvers.py", line 366, in resolve
    for pattern in self.url_patterns:
  File "/home/fious/python3.4.2/lib/python3.4/site-packages/Django-1.8.4-py3.4.egg/django/core/urlresolvers.py", line 402, in url_patterns
    patterns = getattr(self.urlconf_module, "urlpatterns", self.urlconf_module)
  File "/home/fious/python3.4.2/lib/python3.4/site-packages/Django-1.8.4-py3.4.egg/django/core/urlresolvers.py", line 396, in urlconf_module
    self._urlconf_module = import_module(self.urlconf_name)
  File "/home/fious/python3.4.2/lib/python3.4/importlib/__init__.py", line 109, in import_module
    return _bootstrap._gcd_import(name[level:], package, level)
  File "<frozen importlib._bootstrap>", line 2254, in _gcd_import
  File "<frozen importlib._bootstrap>", line 2237, in _find_and_load
  File "<frozen importlib._bootstrap>", line 2226, in _find_and_load_unlocked
  File "<frozen importlib._bootstrap>", line 1200, in _load_unlocked
  File "<frozen importlib._bootstrap>", line 1129, in _exec
  File "<frozen importlib._bootstrap>", line 1471, in exec_module
  File "<frozen importlib._bootstrap>", line 321, in _call_with_frames_removed
  File "/home/fious/mysite/mysite/urls.py", line 12, in <module>
    admin.autodiscover()
  File "/home/fious/python3.4.2/lib/python3.4/site-packages/Django-1.8.4-py3.4.egg/django/contrib/admin/__init__.py", line 24, in autodiscover
    autodiscover_modules('admin', register_to=site)
  File "/home/fious/python3.4.2/lib/python3.4/site-packages/Django-1.8.4-py3.4.egg/django/utils/module_loading.py", line 67, in autodiscover_modules
    for app_config in apps.get_app_configs():
  File "/home/fious/python3.4.2/lib/python3.4/site-packages/Django-1.8.4-py3.4.egg/django/apps/registry.py", line 137, in get_app_configs
    self.check_apps_ready()
  File "/home/fious/python3.4.2/lib/python3.4/site-packages/Django-1.8.4-py3.4.egg/django/apps/registry.py", line 124, in check_apps_ready
    raise AppRegistryNotReady("Apps aren't loaded yet.")
django.core.exceptions.AppRegistryNotReady: Apps aren't loaded yet.

During handling of the above exception, another exception occurred:

Traceback (most recent call last):
  File "/home/fious/python3.4.2/lib/python3.4/site-packages/Django-1.8.4-py3.4.egg/django/template/defaultfilters.py", line 776, in date
    return formats.date_format(value, arg)
  File "/home/fious/python3.4.2/lib/python3.4/site-packages/Django-1.8.4-py3.4.egg/django/utils/formats.py", line 136, in date_format
    return dateformat.format(value, get_format(format or 'DATE_FORMAT', use_l10n=use_l10n))
  File "/home/fious/python3.4.2/lib/python3.4/site-packages/Django-1.8.4-py3.4.egg/django/utils/formats.py", line 108, in get_format
    return getattr(settings, format_type)
  File "/home/fious/python3.4.2/lib/python3.4/site-packages/Django-1.8.4-py3.4.egg/django/conf/__init__.py", line 49, in __getattr__
    return getattr(self._wrapped, name)
AttributeError: 'Settings' object has no attribute 'r'

During handling of the above exception, another exception occurred:

Traceback (most recent call last):
  File "/home/fious/python3.4.2/lib/python3.4/site-packages/Django-1.8.4-py3.4.egg/django/utils/translation/trans_real.py", line 161, in _add_installed_apps_translations
    app_configs = reversed(list(apps.get_app_configs()))
  File "/home/fious/python3.4.2/lib/python3.4/site-packages/Django-1.8.4-py3.4.egg/django/apps/registry.py", line 137, in get_app_configs
    self.check_apps_ready()
  File "/home/fious/python3.4.2/lib/python3.4/site-packages/Django-1.8.4-py3.4.egg/django/apps/registry.py", line 124, in check_apps_ready
    raise AppRegistryNotReady("Apps aren't loaded yet.")
django.core.exceptions.AppRegistryNotReady: Apps aren't loaded yet.

During handling of the above exception, another exception occurred:

Traceback (most recent call last):
  File "/home/fious/python3.4.2/lib/python3.4/site-packages/Django-1.8.4-py3.4.egg/django/core/handlers/wsgi.py", line 189, in __call__
    response = self.get_response(request)
  File "/home/fious/python3.4.2/lib/python3.4/site-packages/Django-1.8.4-py3.4.egg/django/core/handlers/base.py", line 218, in get_response
    response = self.handle_uncaught_exception(request, resolver, sys.exc_info())
  File "/home/fious/python3.4.2/lib/python3.4/site-packages/Django-1.8.4-py3.4.egg/django/core/handlers/base.py", line 261, in handle_uncaught_exception
    return debug.technical_500_response(request, *exc_info)
  File "/home/fious/python3.4.2/lib/python3.4/site-packages/Django-1.8.4-py3.4.egg/django/views/debug.py", line 97, in technical_500_response
    html = reporter.get_traceback_html()
  File "/home/fious/python3.4.2/lib/python3.4/site-packages/Django-1.8.4-py3.4.egg/django/views/debug.py", line 384, in get_traceback_html
    return t.render(c)
  File "/home/fious/python3.4.2/lib/python3.4/site-packages/Django-1.8.4-py3.4.egg/django/template/base.py", line 209, in render
    return self._render(context)
  File "/home/fious/python3.4.2/lib/python3.4/site-packages/Django-1.8.4-py3.4.egg/django/template/base.py", line 201, in _render
    return self.nodelist.render(context)
  File "/home/fious/python3.4.2/lib/python3.4/site-packages/Django-1.8.4-py3.4.egg/django/template/base.py", line 903, in render
    bit = self.render_node(node, context)
  File "/home/fious/python3.4.2/lib/python3.4/site-packages/Django-1.8.4-py3.4.egg/django/template/debug.py", line 79, in render_node
    return node.render(context)
  File "/home/fious/python3.4.2/lib/python3.4/site-packages/Django-1.8.4-py3.4.egg/django/template/debug.py", line 89, in render
    output = self.filter_expression.resolve(context)
  File "/home/fious/python3.4.2/lib/python3.4/site-packages/Django-1.8.4-py3.4.egg/django/template/base.py", line 674, in resolve
    new_obj = func(obj, *arg_vals)
  File "/home/fious/python3.4.2/lib/python3.4/site-packages/Django-1.8.4-py3.4.egg/django/template/defaultfilters.py", line 779, in date
    return format(value, arg)
  File "/home/fious/python3.4.2/lib/python3.4/site-packages/Django-1.8.4-py3.4.egg/django/utils/dateformat.py", line 345, in format
    return df.format(format_string)
  File "/home/fious/python3.4.2/lib/python3.4/site-packages/Django-1.8.4-py3.4.egg/django/utils/dateformat.py", line 37, in format
    pieces.append(force_text(getattr(self, piece)()))
  File "/home/fious/python3.4.2/lib/python3.4/site-packages/Django-1.8.4-py3.4.egg/django/utils/dateformat.py", line 270, in r
    return self.format('D, j M Y H:i:s O')
  File "/home/fious/python3.4.2/lib/python3.4/site-packages/Django-1.8.4-py3.4.egg/django/utils/dateformat.py", line 37, in format
    pieces.append(force_text(getattr(self, piece)()))
  File "/home/fious/python3.4.2/lib/python3.4/site-packages/Django-1.8.4-py3.4.egg/django/utils/encoding.py", line 90, in force_text
    s = six.text_type(s)
  File "/home/fious/python3.4.2/lib/python3.4/site-packages/Django-1.8.4-py3.4.egg/django/utils/functional.py", line 141, in __text_cast
    return func(*self.__args, **self.__kw)
  File "/home/fious/python3.4.2/lib/python3.4/site-packages/Django-1.8.4-py3.4.egg/django/utils/translation/__init__.py", line 84, in ugettext
    return _trans.ugettext(message)
  File "/home/fious/python3.4.2/lib/python3.4/site-packages/Django-1.8.4-py3.4.egg/django/utils/translation/trans_real.py", line 321, in gettext
    return do_translate(message, 'gettext')
  File "/home/fious/python3.4.2/lib/python3.4/site-packages/Django-1.8.4-py3.4.egg/django/utils/translation/trans_real.py", line 304, in do_translate
    _default = _default or translation(settings.LANGUAGE_CODE)
  File "/home/fious/python3.4.2/lib/python3.4/site-packages/Django-1.8.4-py3.4.egg/django/utils/translation/trans_real.py", line 206, in translation
    _translations[language] = DjangoTranslation(language)
  File "/home/fious/python3.4.2/lib/python3.4/site-packages/Django-1.8.4-py3.4.egg/django/utils/translation/trans_real.py", line 116, in __init__
    self._add_installed_apps_translations()
  File "/home/fious/python3.4.2/lib/python3.4/site-packages/Django-1.8.4-py3.4.egg/django/utils/translation/trans_real.py", line 164, in _add_installed_apps_translations
    "The translation infrastructure cannot be initialized before the "
django.core.exceptions.AppRegistryNotReady: The translation infrastructure cannot be initialized before the apps registry is ready. Check that you don't make non-lazy gettext calls at import time.
[pid: 3421|app: 0|req: 3/3] 127.0.0.1 () {38 vars in 607 bytes} [Sun Oct 25 08:35:06 2015] GET /hello/ => generated 0 bytes in 144 msecs (HTTP/1.1 500) 0 headers in 0 bytes (0 switches on core 0)
...brutally killing workers...
worker 1 buried after 1 seconds
binary reloading uWSGI...
chdir() to /home/fious/mysite
closing all non-uwsgi socket fds > 2 (max_fd = 1024)...
found fd 3 mapped to socket 0 (:8001)
running /home/fious/uwsgi/uwsgi
[uWSGI] getting INI configuration from uwsgi.ini
*** Starting uWSGI 2.0.11.2 (64bit) on [Sun Oct 25 16:50:18 2015] ***
compiled with version: 4.4.7 20120313 (Red Hat 4.4.7-4) on 24 October 2015 19:34:43
os: Linux-2.6.32-431.el6.x86_64 #1 SMP Fri Nov 22 03:15:09 UTC 2013
nodename: localhost.localdomain
machine: x86_64
clock source: unix
pcre jit disabled
detected number of CPU cores: 1
current working directory: /home/fious/mysite
detected binary path: /home/fious/uwsgi/uwsgi
chdir() to /home/fious/mysite/mysite
your processes number limit is 1024
your memory page size is 4096 bytes
detected max file descriptor number: 1024
lock engine: pthread robust mutexes
thunder lock: disabled (you can enable it with --thunder-lock)
uwsgi socket 0 inherited INET address :8001 fd 3
Python version: 3.4.2 (default, Oct 18 2015, 15:32:19)  [GCC 4.4.7 20120313 (Red Hat 4.4.7-4)]
Python main interpreter initialized at 0xc6ddf0
python threads support enabled
your server socket listen backlog is limited to 100 connections
your mercy for graceful operations on workers is 60 seconds
mapped 145520 bytes (142 KB) for 1 cores
*** Operational MODE: single process ***
added /home/fious/mysite/ to pythonpath.
  File "/home/fious/mysite/uwsgi_app.py", line 14
    django.setup()
    ^
IndentationError: unexpected indent
unable to load app 0 (mountpoint='') (callable not found or import error)
*** no app loaded. going in full dynamic mode ***
*** uWSGI is running in multiple interpreter mode ***
gracefully (RE)spawned uWSGI master process (pid: 3419)
spawned uWSGI worker 1 (pid: 4291, cores: 1)
*** Starting uWSGI 2.0.11.2 (64bit) on [Tue Oct 27 20:10:24 2015] ***
compiled with version: 4.4.7 20120313 (Red Hat 4.4.7-4) on 24 October 2015 19:34:43
os: Linux-2.6.32-431.el6.x86_64 #1 SMP Fri Nov 22 03:15:09 UTC 2013
nodename: localhost.localdomain
machine: x86_64
clock source: unix
pcre jit disabled
detected number of CPU cores: 1
current working directory: /home/fious/mysite
detected binary path: /home/fious/uwsgi/uwsgi
chdir() to /home/fious/mysite/mysite
your processes number limit is 1024
your memory page size is 4096 bytes
detected max file descriptor number: 1024
lock engine: pthread robust mutexes
thunder lock: disabled (you can enable it with --thunder-lock)
uwsgi socket 0 bound to TCP address :8001 fd 3
Python version: 3.4.2 (default, Oct 18 2015, 15:32:19)  [GCC 4.4.7 20120313 (Red Hat 4.4.7-4)]
Python main interpreter initialized at 0x2862f30
python threads support enabled
your server socket listen backlog is limited to 100 connections
your mercy for graceful operations on workers is 60 seconds
mapped 145520 bytes (142 KB) for 1 cores
*** Operational MODE: single process ***
added /home/fious/mysite/ to pythonpath.
  File "/home/fious/mysite/uwsgi_app.py", line 14
    django.setup()
    ^
IndentationError: unexpected indent
unable to load app 0 (mountpoint='') (callable not found or import error)
*** no app loaded. going in full dynamic mode ***
*** uWSGI is running in multiple interpreter mode ***
spawned uWSGI master process (pid: 2763)
spawned uWSGI worker 1 (pid: 2764, cores: 1)
--- no python application found, check your startup logs for errors ---
[pid: 2764|app: -1|req: -1/1] 127.0.0.1 () {36 vars in 576 bytes} [Tue Oct 27 20:10:48 2015] GET /hello/ => generated 21 bytes in 0 msecs (HTTP/1.1 500) 2 headers in 83 bytes (0 switches on core 0)
--- no python application found, check your startup logs for errors ---
[pid: 2764|app: -1|req: -1/2] 127.0.0.1 () {36 vars in 586 bytes} [Tue Oct 27 20:10:48 2015] GET /favicon.ico => generated 21 bytes in 0 msecs (HTTP/1.1 500) 2 headers in 83 bytes (0 switches on core 0)
*** Starting uWSGI 2.0.11.2 (64bit) on [Tue Oct 27 20:18:51 2015] ***
compiled with version: 4.4.7 20120313 (Red Hat 4.4.7-4) on 24 October 2015 19:34:43
os: Linux-2.6.32-431.el6.x86_64 #1 SMP Fri Nov 22 03:15:09 UTC 2013
nodename: localhost.localdomain
machine: x86_64
clock source: unix
pcre jit disabled
detected number of CPU cores: 1
current working directory: /home/fious/mysite
detected binary path: /home/fious/uwsgi/uwsgi
chdir() to /home/fious/mysite/
your processes number limit is 1024
your memory page size is 4096 bytes
detected max file descriptor number: 1024
lock engine: pthread robust mutexes
thunder lock: disabled (you can enable it with --thunder-lock)
probably another instance of uWSGI is running on the same address (127.0.0.1:8001).
bind(): Address already in use [core/socket.c line 769]
invalid request block size: 21573 (max 4096)...skip
--- no python application found, check your startup logs for errors ---
[pid: 2764|app: -1|req: -1/3] 127.0.0.1 () {36 vars in 576 bytes} [Tue Oct 27 20:19:14 2015] GET /hello/ => generated 21 bytes in 0 msecs (HTTP/1.1 500) 2 headers in 83 bytes (0 switches on core 0)
--- no python application found, check your startup logs for errors ---
[pid: 2764|app: -1|req: -1/4] 127.0.0.1 () {36 vars in 586 bytes} [Tue Oct 27 20:19:14 2015] GET /favicon.ico => generated 21 bytes in 0 msecs (HTTP/1.1 500) 2 headers in 83 bytes (0 switches on core 0)
--- no python application found, check your startup logs for errors ---
[pid: 2764|app: -1|req: -1/5] 127.0.0.1 () {38 vars in 607 bytes} [Tue Oct 27 20:20:18 2015] GET /hello/ => generated 21 bytes in 0 msecs (HTTP/1.1 500) 2 headers in 83 bytes (0 switches on core 0)
...brutally killing workers...
worker 1 buried after 1 seconds
binary reloading uWSGI...
chdir() to /home/fious/mysite
closing all non-uwsgi socket fds > 2 (max_fd = 1024)...
found fd 3 mapped to socket 0 (:8001)
running /home/fious/uwsgi/uwsgi
[uWSGI] getting INI configuration from uwsgi.ini
*** Starting uWSGI 2.0.11.2 (64bit) on [Tue Oct 27 20:20:58 2015] ***
compiled with version: 4.4.7 20120313 (Red Hat 4.4.7-4) on 24 October 2015 19:34:43
os: Linux-2.6.32-431.el6.x86_64 #1 SMP Fri Nov 22 03:15:09 UTC 2013
nodename: localhost.localdomain
machine: x86_64
clock source: unix
pcre jit disabled
detected number of CPU cores: 1
current working directory: /home/fious/mysite
detected binary path: /home/fious/uwsgi/uwsgi
chdir() to /home/fious/mysite/
your processes number limit is 1024
your memory page size is 4096 bytes
detected max file descriptor number: 1024
lock engine: pthread robust mutexes
thunder lock: disabled (you can enable it with --thunder-lock)
uwsgi socket 0 bound to TCP address 127.0.0.1:8001 fd 3
Python version: 3.4.2 (default, Oct 18 2015, 15:32:19)  [GCC 4.4.7 20120313 (Red Hat 4.4.7-4)]
Python main interpreter initialized at 0x147e2b0
python threads support enabled
your server socket listen backlog is limited to 100 connections
your mercy for graceful operations on workers is 60 seconds
mapped 145520 bytes (142 KB) for 1 cores
*** Operational MODE: single process ***
added /home/fious/mysite/ to pythonpath.
added /home/fious/mysite/mysite/ to pythonpath.
Traceback (most recent call last):
  File "/home/fious/mysite/uwsgi_app.py", line 4, in <module>
    reload(sys)
NameError: name 'reload' is not defined
unable to load app 0 (mountpoint='') (callable not found or import error)
*** no app loaded. going in full dynamic mode ***
*** uWSGI is running in multiple interpreter mode ***
gracefully (RE)spawned uWSGI master process (pid: 2763)
spawned uWSGI worker 1 (pid: 3695, cores: 1)
